<?xml version="1.0"?>
<robot name="asv_description" xmlns:xacro="http://www.ros.org/wiki/xacro">
	<xacro:include filename="$(find asv_description)/urdf/common_properties.xacro"/>
	<link name="base_footprint">
		<inertial>
			<mass value="0.0001"/>
			<origin xyz="0 0 0"/>
			<inertia ixx="0.0001" ixy="0.0" ixz="0.0" iyy="0.0001" iyz="0.0" izz="0.0001"/>
		</inertial>
		<visual>
			<origin rpy="0 0 0" xyz="0 0 0"/>
			<geometry>
				<box size="0.001 0.001 0.001"/>
			</geometry>
		</visual>
	</link>
	<joint name="base_footprint_joint" type="fixed">
		<origin rpy="${PI/2} 0 0" xyz="0 0 0.5"/>
		<parent link="base_footprint"/>
		<child link="base_link"/>
	</joint>
	<link name="base_link">
		<inertial>
			<origin rpy="0 0 0" xyz="0.00081248 -0.14905 0.79199"/>
			<mass value="5.331"/>
			<inertia ixx="0" ixy="0" ixz="0" iyy="0" iyz="0" izz="0"/>
		</inertial>
		<visual>
			<origin rpy="0 0 0" xyz="0 0 0"/>
			<geometry>
				<mesh filename="$(arg path)/base_link.STL"/>
			</geometry>
			<xacro:insert_block name="fiber"/>
		</visual>
		<collision>
			<origin rpy="0 0 0" xyz="0 0 0"/>
			<geometry>
				<mesh filename="$(arg path)/base_link.STL"/>
			</geometry>
		</collision>
	</link>
	<link name="thruster_left">
		<inertial>
			<origin rpy="0 0 0" xyz="-0.35951 -0.36784 0.94138"/>
			<mass value="0.19486"/>
			<inertia ixx="3.3635E-05" ixy="3.3962E-09" ixz="1.273E-07" iyy="3.3048E-05" iyz="-8.343E-07" izz="1.1884E-06"/>
		</inertial>
		<visual>
			<origin rpy="0 0 0" xyz="0 0 0"/>
			<geometry>
				<mesh filename="$(arg path)/thruster_left.STL"/>
			</geometry>
			<xacro:insert_block name="fiber"/>
		</visual>
		<collision>
			<origin rpy="0 0 0" xyz="0 0 0"/>
			<geometry>
				<mesh filename="$(arg path)/thruster_left.STL"/>
			</geometry>
		</collision>
	</link>
	<joint name="body_to_thruster_left" type="continuous">
		<origin rpy="0 0 0" xyz="0 0 0"/>
		<parent link="base_link"/>
		<child link="thruster_left"/>
		<axis xyz="0 0 0"/>
		<!--<limit effort="30" lower="-32000" upper="32000" velocity="1.0"/>
		<dynamics damping="0.1" friction="0.1"/>-->
	</joint>
	<link name="thruster_right">
		<inertial>
			<origin rpy="0 0 0" xyz="0.35962 -0.36784 0.94138"/>
			<mass value="0.19487"/>
			<inertia ixx="3.3633E-05" ixy="-8.3928E-09" ixz="-3.3111E-07" iyy="3.3048E-05" iyz="-8.3442E-07" izz="1.1913E-06"/>
		</inertial>
		<visual>
			<origin rpy="0 0 0" xyz="0 0 0"/>
			<geometry>
				<mesh filename="$(arg path)/thruster_right.STL"/>
			</geometry>
			<material name="">
				<color rgba="0.79216 0.81961 0.93333 1"/>
			</material>
		</visual>
		<collision>
			<origin rpy="0 0 0" xyz="0 0 0"/>
			<geometry>
				<mesh filename="$(arg path)/thruster_right.STL"/>
			</geometry>
		</collision>
	</link>
	<joint name="body_to_thruster_right" type="continuous">
		<origin rpy="0 0 0" xyz="0 0 0"/>
		<parent link="base_link"/>
		<child link="thruster_right"/>
		<axis xyz="0 0 0"/>
		<!--<limit effort="30" lower="-32000" upper="32000" velocity="1.0"/>
		<dynamics damping="0.1" friction="0.1"/>-->
	</joint>
	<link name="top_body">
		<inertial>
			<origin rpy="0 0 0" xyz="9.7484E-05 0.024673 0.7522"/>
			<mass value="2.1573"/>
			<inertia ixx="0.016871" ixy="-8.9301E-06" ixz="-3.158E-05" iyy="0.026678" iyz="-0.0021608" izz="0.010957"/>
		</inertial>
		<visual>
			<origin rpy="0 0 0" xyz="0 0 0"/>
			<geometry>
				<mesh filename="$(arg path)/top_body.STL"/>
			</geometry>
			<xacro:insert_block name="fiber"/>
		</visual>
		<collision>
			<origin rpy="0 0 0" xyz="0 0 0"/>
			<geometry>
				<mesh filename="$(arg path)/top_body.STL"/>
			</geometry>
		</collision>
	</link>
	<joint name="base_to_top" type="fixed">
		<origin rpy="0 0 0" xyz="0 0 0"/>
		<parent link="base_link"/>
		<child link="top_body"/>
		<axis xyz="0 0 0"/>
	</joint>
	<link name="sensor_pod">
		<inertial>
			<origin rpy="0 0 0" xyz="-0.013295 0.078554 0.22706"/>
			<mass value="0.6495"/>
			<inertia ixx="8.2722E-07" ixy="-6.7581E-06" ixz="3.6677E-05" iyy="0.0016822" iyz="1.4742E-07" izz="0.0016814"/>
		</inertial>
		<visual>
			<origin rpy="0 0 0" xyz="0 0 0"/>
			<geometry>
				<mesh filename="$(arg path)/sensor_pod.STL"/>
			</geometry>
			<material name="">
				<color rgba="0.79216 0.81961 0.93333 1"/>
			</material>
		</visual>
		<collision>
			<origin rpy="0 0 0" xyz="0 0 0"/>
			<geometry>
				<mesh filename="$(arg path)/sensor_pod.STL"/>
			</geometry>
		</collision>
	</link>
	<joint name="top_body_to_pod" type="fixed">
		<origin rpy="0 0 0" xyz="0 0 0"/>
		<parent link="top_body"/>
		<child link="sensor_pod"/>
		<axis xyz="0 0 0"/>
	</joint>
	<link name="lidar">
		<inertial>
			<origin rpy="0 0 0" xyz="0.007675 0.19969 0.070677"/>
			<mass value="8.4876E-05"/>
			<inertia ixx="7.4827E-08" ixy="1.2593E-09" ixz="-7.9614E-10" iyy="1.3889E-07" iyz="-1.1497E-08" izz="7.6608E-08"/>
		</inertial>
		<visual>
			<origin rpy="0 0 0" xyz="0 0 0"/>
			<geometry>
				<mesh filename="$(arg path)/lidar.STL"/>
			</geometry>
			<material name="">
				<color rgba="0.79216 0.81961 0.93333 1"/>
			</material>
		</visual>
		<collision>
			<origin rpy="0 0 0" xyz="0 0 0"/>
			<geometry>
				<mesh filename="$(arg path)/lidar.STL"/>
			</geometry>
		</collision>
	</link>
	<joint name="pod_to_lidar" type="continuous">
		<origin rpy="0 0 0" xyz="0 0 0"/>
		<parent link="sensor_pod"/>
		<child link="lidar"/>
		<axis xyz="1 0 0"/>
	</joint>
	<link name="camera_mount">
		<inertial>
			<origin rpy="0 0 0" xyz="-1.1102E-16 0.22615 0.20972"/>
			<mass value="0.05273"/>
			<inertia ixx="0" ixy="0" ixz="0" iyy="0" iyz="0" izz="0"/>
		</inertial>
		<visual>
			<origin rpy="0 0 0" xyz="0 0 0"/>
			<geometry>
				<mesh filename="$(arg path)/camera_mount.STL"/>
			</geometry>
			<material name="">
				<color rgba="1 1 1 0.875"/>
			</material>
		</visual>
		<collision>
			<origin rpy="0 0 0" xyz="0 0 0"/>
			<geometry>
				<mesh filename="$(arg path)/camera_mount.STL"/>
			</geometry>
		</collision>
	</link>
	<joint name="pod_to_camera_mount" type="fixed">
		<origin rpy="0 0 0" xyz="0 0 0"/>
		<parent link="sensor_pod"/>
		<child link="camera_mount"/>
		<axis xyz="0 0 0"/>
	</joint>
	<link name="camera">
		<inertial>
			<origin rpy="0 0 0" xyz="0.00010371 0.31918 0.16605"/>
			<mass value="0.042277"/>
			<inertia ixx="1.4944E-05" ixy="-4.7327E-08" ixz="5.3606E-08" iyy="3.1817E-06" iyz="3.9498E-06" izz="1.1765E-05"/>
		</inertial>
		<visual>
			<origin rpy="0 0 0" xyz="0 0 0"/>
			<geometry>
				<mesh filename="$(arg path)/camera.STL"/>
			</geometry>
			<material name="">
				<color rgba="0.019608 0.019608 0.019608 1"/>
			</material>
		</visual>
		<collision>
			<origin rpy="0 0 0" xyz="0 0 0"/>
			<geometry>
				<mesh filename="$(arg path)/camera.STL"/>
			</geometry>
		</collision>
	</link>
	<joint name="mount_to_camera" type="fixed">
		<origin rpy="0 0 0" xyz="0 0 0"/>
		<parent link="camera_mount"/>
		<child link="camera"/>
		<axis xyz="0 0 0"/>
	</joint>
	<link name="garmin_mount">
		<inertial>
			<origin rpy="0 0 0" xyz="-5.5511E-17 0.20372 0.27749"/>
			<mass value="0.064841"/>
			<inertia ixx="0" ixy="0" ixz="0" iyy="0" iyz="0" izz="0"/>
		</inertial>
		<visual>
			<origin rpy="0 0 0" xyz="0 0 0"/>
			<geometry>
				<mesh filename="$(arg path)/garmin_mount.STL"/>
			</geometry>
			<material name="">
				<color rgba="0.79216 0.81961 0.93333 1"/>
			</material>
		</visual>
		<collision>
			<origin rpy="0 0 0" xyz="0 0 0"/>
			<geometry>
				<mesh filename="$(arg path)/garmin_mount.STL"/>
			</geometry>
		</collision>
	</link>
	<joint name="pod_to_garmin_mount" type="fixed">
		<origin rpy="0 0 0" xyz="0 0 0"/>
		<parent link="sensor_pod"/>
		<child link="garmin_mount"/>
		<axis xyz="0 0 0"/>
	</joint>
	<link name="garmin">
		<inertial>
			<origin rpy="0 0 0" xyz="-1.1102E-16 0.23834 0.29679"/>
			<mass value="0.3356"/>
			<inertia ixx="0" ixy="0" ixz="0" iyy="0" iyz="0" izz="0"/>
		</inertial>
		<visual>
			<origin rpy="0 0 0" xyz="0 0 0"/>
			<geometry>
				<mesh filename="$(arg path)/garmin.STL"/>
			</geometry>
			<material name="">
				<color rgba="0.79216 0.81961 0.93333 1"/>
			</material>
		</visual>
		<collision>
			<origin rpy="0 0 0" xyz="0 0 0"/>
			<geometry>
				<mesh filename="$(arg path)/garmin.STL"/>
			</geometry>
		</collision>
	</link>
	<joint name="gps_to_mount" type="fixed">
		<origin rpy="0 0 0" xyz="0 0 0"/>
		<parent link="garmin_mount"/>
		<child link="garmin"/>
		<axis xyz="0 0 0"/>
	</joint>
</robot>